<?xml version="1.0" ?>

<robot name="wam_4dof">

    <material name="red">
        <color rgba="1 0 0 1"/>
    </material>

    <material name="green">
        <color rgba="0 1 0 1"/>
    </material>

    <material name="blue">
        <color rgba="0 0 1 1"/>
    </material>

    <material name="dark">
        <color rgba=".25 .25 .25 1"/>
    </material>

    <material name="lightest_grey">
        <color rgba="0.85 0.85 0.85 1"/>
    </material>

    <material name="light_grey">
        <color rgba="0.78 0.75 0.7 1"/>
    </material>

    <material name="dark_grey">
        <color rgba="0.6 0.6 0.6 1"/>
    </material>

    <link name="links/world"/>

    <link name="links/base">
        <inertial>
            <mass value="9.97059584"/>
            <origin xyz="0.1998 -0.1260 0.2053" rpy="1.5605 0.0894 0.6977"/>
            <inertia ixx="0.08709498" ixy="0." ixz="0." iyy="0.13911978" iyz="0." izz="0.18350061"/>
        </inertial>
        <visual>
            <origin xyz="0.22 0.14 0." rpy="0 0 0"/>
            <geometry name="wam_base_visual">
                <mesh filename="base_link_fine.stl"/>
            </geometry>
            <material name="light_grey"/>
        </visual>
        <collision>
            <origin xyz="0.22 0.14 0." rpy="0 0 0"/>
            <geometry name="wam_base_collision">
                <mesh filename="base_link_convex.stl"/>
            </geometry>
        </collision>
    </link>

    <link name="frames/0">
        <visual>
            <origin xyz="0.075 0 0" rpy="0 1.570796327 0"/>
            <geometry name="x_axis">
                <cylinder length="0.15" radius="0.01"/>
            </geometry>
            <material name="red"/>
        </visual>
        <visual>
            <origin xyz="0 0.075 0" rpy="1.570796327 0 0"/>
            <geometry name="y_axis">
                <cylinder length="0.15" radius="0.01" />
            </geometry>
            <material name="green"/>
        </visual>
        <visual>
            <origin xyz="0 0 0.075" rpy="0 0 0"/>
            <geometry name="z_axis">
                <cylinder length="0.15" radius="0.01"/>
            </geometry>
            <material name="blue"/>
        </visual>
    </link>

    <link name="links/shoulder_yaw">
        <inertial>
            <mass value="10.76768767"/>
            <origin xyz="-0.0044 -0.0007 -0.1219" rpy="1.6016 0.0973 1.5751"/>
            <inertia ixx="0.09044192" ixy="0." ixz="0." iyy="0.11309685" iyz="0." izz="0.13508855"/>
        </inertial>
        <visual>
            <origin rpy="0 0 0" xyz="0 0 0"/>
            <geometry name="link_shoulder_yaw_visual">
                <mesh filename="shoulder_link_fine.stl"/>
            </geometry>
            <material name="light_grey"/>
        </visual>
        <collision>
            <origin rpy="0 0 0" xyz="0 0 0"/>
            <geometry name="link_shoulder_yaw_collision1">
                <mesh filename="shoulder_link_convex_decomposition_p1.stl"/>
            </geometry>
        </collision>
        <collision>
            <origin rpy="0 0 0" xyz="0 0 0"/>
            <geometry name="link_shoulder_yaw_collision2">
                <mesh filename="shoulder_link_convex_decomposition_p2.stl"/>
            </geometry>
        </collision>
        <collision>
            <origin rpy="0 0 0" xyz="0 0 0"/>
            <geometry name="link_shoulder_yaw_collision3">
                <mesh filename="shoulder_link_convex_decomposition_p3.stl"/>
            </geometry>
        </collision>
    </link>

    <link name="frames/1">
        <visual>
            <origin xyz="0.075 0 0" rpy="0 1.570796327 0"/>
            <geometry name="x_axis">
                <cylinder length="0.15" radius="0.01"/>
            </geometry>
            <material name="red"/>
        </visual>
        <visual>
            <origin xyz="0 0.075 0" rpy="1.570796327 0 0"/>
            <geometry name="y_axis">
                <cylinder length="0.15" radius="0.01" />
            </geometry>
            <material name="green"/>
        </visual>
        <visual>
            <origin xyz="0 0 0.075" rpy="0 0 0"/>
            <geometry name="z_axis">
                <cylinder length="0.15" radius="0.01"/>
            </geometry>
            <material name="blue"/>
        </visual>
    </link>

    <link name="links/shoulder_pitch">
        <inertial>
            <mass value="3.87493756"/>
            <origin xyz="-0.0024 -0.0154 0.0311" rpy="0.5527 -0.0348 -1.5459"/>
            <inertia ixx="0.01264653" ixy="0." ixz="0." iyy="0.01671014" iyz="0." izz="0.02142072"/>
        </inertial>
        <visual>
            <origin rpy="0 0 0" xyz="0 0 0"/>
            <geometry name="link_shoulder_pitch_visual">
                <mesh filename="shoulder_pitch_link_fine.stl"/>
            </geometry>
            <material name="dark_grey"/>
        </visual>
        <collision>
            <origin rpy="0 0 0" xyz="0 0 0"/>
            <geometry name="link_shoulder_pitch_collision">
                <mesh filename="shoulder_pitch_link_convex.stl"/>
            </geometry>
        </collision>
    </link>

    <link name="frames/2">
        <visual>
            <origin xyz="0.075 0 0" rpy="0 1.570796327 0"/>
            <geometry name="x_axis">
                <cylinder length="0.15" radius="0.01"/>
            </geometry>
            <material name="red"/>
        </visual>
        <visual>
            <origin xyz="0 0.075 0" rpy="1.570796327 0 0"/>
            <geometry name="y_axis">
                <cylinder length="0.15" radius="0.01" />
            </geometry>
            <material name="green"/>
        </visual>
        <visual>
            <origin xyz="0 0 0.075" rpy="0 0 0"/>
            <geometry name="z_axis">
                <cylinder length="0.15" radius="0.01"/>
            </geometry>
            <material name="blue"/>
        </visual>
    </link>

    <link name="links/upper_arm">
        <inertial>
            <mass value="1.80228141"/>
            <origin xyz="0.0067 0.0000 0.3425" rpy="0.3219 -1.4307 -1.8954"/>
            <inertia ixx="0.00313419" ixy="0." ixz="0." iyy="0.05922120" iyz="0." izz="0.05927132"/>
        </inertial>
        <visual>
            <origin rpy="0 0 0" xyz="0 0 0"/>
            <geometry name="link_upper_arm_visual">
                <mesh filename="upper_arm_link_fine.stl"/>
            </geometry>
            <material name="dark"/>
        </visual>
        <collision>
            <origin rpy="0 0 0" xyz="0 0 0"/>
            <geometry name="link_upper_arm_collision1">
                <mesh filename="upper_arm_link_convex_decomposition_p1.stl"/>
            </geometry>
        </collision>
        <collision>
            <origin rpy="0 0 0" xyz="0 0 0"/>
            <geometry name="link_upper_arm_collision1">
                <mesh filename="upper_arm_link_convex_decomposition_p2.stl"/>
            </geometry>
        </collision>
    </link>

    <link name="frames/3">
        <visual>
            <origin xyz="0.075 0 0" rpy="0 1.570796327 0"/>
            <geometry name="x_axis">
                <cylinder length="0.15" radius="0.01"/>
            </geometry>
            <material name="red"/>
        </visual>
        <visual>
            <origin xyz="0 0.075 0" rpy="1.570796327 0 0"/>
            <geometry name="y_axis">
                <cylinder length="0.15" radius="0.01" />
            </geometry>
            <material name="green"/>
        </visual>
        <visual>
            <origin xyz="0 0 0.075" rpy="0 0 0"/>
            <geometry name="z_axis">
                <cylinder length="0.15" radius="0.01"/>
            </geometry>
            <material name="blue"/>
        </visual>
    </link>

    <link name="links/forearm">
        <inertial>
            <mass value="1.06513649"/>
            <origin xyz="-0.0340 -0.1405 -0.0000" rpy="0.1006 -1.4741 3.0417"/>
            <inertia ixx="0.00181989" ixy="0." ixz="0." iyy="0.01864102" iyz="0." izz="0.01891661"/>
        </inertial>
        <visual>
            <origin rpy="0 0 0" xyz="0 0 0"/>
            <geometry name="link_forearm_visual1">
                <mesh filename="elbow_link_fine.stl"/>
            </geometry>
            <material name="lightest_grey"/>
        </visual>
        <visual>
            <origin rpy="1.570796 0 0" xyz="-0.045 -0.214 0"/>
            <geometry name="link_forearm_visual2">
                <cylinder radius=".0445" length="0.272"/>
            </geometry>
            <material name="dark"/>
        </visual>
        <collision>
            <origin rpy="0 0 0" xyz="0 0 0"/>
            <geometry name="link_forearm_collision1">
                <mesh filename="elbow_link_convex.stl"/>
            </geometry>
        </collision>
        <collision>
            <origin rpy="1.570796 0 0" xyz="-0.045 -0.214 0"/>
            <geometry name="link_forearm_collision2">
                <cylinder radius=".0445" length="0.272"/>
            </geometry>
        </collision>
    </link>

    <link name="frames/4">
        <visual>
            <origin xyz="0.075 0 0" rpy="0 1.570796327 0"/>
            <geometry name="x_axis">
                <cylinder length="0.15" radius="0.01"/>
            </geometry>
            <material name="red"/>
        </visual>
        <visual>
            <origin xyz="0 0.075 0" rpy="1.570796327 0 0"/>
            <geometry name="y_axis">
                <cylinder length="0.15" radius="0.01" />
            </geometry>
            <material name="green"/>
        </visual>
        <visual>
            <origin xyz="0 0 0.075" rpy="0 0 0"/>
            <geometry name="z_axis">
                <cylinder length="0.15" radius="0.01"/>
            </geometry>
            <material name="blue"/>
        </visual>
    </link>

    <link name="frames/5">
        <inertial>
            <mass value="0.15"/>
            <origin xyz="0 0 0"/>
            <inertia ixx="0.0000001" ixy="0." ixz="0." iyy="0.0000001" iyz="0." izz="0.0000001"/>
        </inertial>
        <visual>
            <origin xyz="0.075 0 0" rpy="0 1.570796327 0"/>
            <geometry name="x_axis">
                <cylinder length="0.15" radius="0.01"/>
            </geometry>
            <material name="red"/>
        </visual>
        <visual>
            <origin xyz="0 0.075 0" rpy="1.570796327 0 0"/>
            <geometry name="y_axis">
                <cylinder length="0.15" radius="0.01" />
            </geometry>
            <material name="green"/>
        </visual>
        <visual>
            <origin xyz="0 0 0.075" rpy="0 0 0"/>
            <geometry name="z_axis">
                <cylinder length="0.15" radius="0.01"/>
            </geometry>
            <material name="blue"/>
        </visual>
    </link>

    <joint name="transformations/base" type="fixed">
        <parent link="links/world"/>
        <child link="links/base"/>
        <origin xyz="0 0 1.2" rpy="0 0 0"/>
    </joint>

    <joint name="transformations/frames/0" type="fixed">
        <origin xyz="0.22 0.14 0.346" rpy="0 0 0"/>
        <parent link="links/base"/>
        <child link="frames/0"/>
    </joint>

    <joint name="joints/shoulder_yaw" type="revolute">
        <origin xyz="0.22 0.14 0.346" rpy="0 0 0"/>
        <parent link="links/base"/>
        <child link="links/shoulder_yaw"/>
        <axis xyz="0 0 1"/>
        <dynamics damping="1.31174" friction="1.70477"/>
        <limit effort="1500" lower="-2.6" upper="2.6" velocity="200"/>
    </joint>

    <joint name="transformations/frames/1" type="fixed">
        <origin xyz="0. 0. 0." rpy="-1.570796 0 0"/>
        <parent link="links/shoulder_yaw"/>
        <child link="frames/1"/>
    </joint>

    <joint name="joints/shoulder_pitch" type="revolute">
        <origin xyz="0 0 0" rpy="-1.570796 0 0"/>
        <parent link="links/shoulder_yaw"/>
        <child link="links/shoulder_pitch"/>
        <axis xyz="0 0 1"/>
        <dynamics damping="0.492821" friction="1.43072"/>
        <limit effort="1250" lower="-2.0" upper="2.0" velocity="200"/>
    </joint>

    <joint name="transformations/frames/2" type="fixed">
        <origin xyz="0. 0. 0." rpy="1.570796 0 0"/>
        <parent link="links/shoulder_pitch"/>
        <child link="frames/2"/>
    </joint>

    <joint name="joints/shoulder_roll" type="revolute">
        <origin xyz="0 0 0" rpy="1.570796 0 0"/>
        <parent link="links/shoulder_pitch"/>
        <child link="links/upper_arm"/>
        <axis xyz="0 0 1"/>
        <dynamics damping="1.48827" friction="0.685072"/>
        <limit effort="400" lower="-2.8" upper="2.8" velocity="200"/>
    </joint>

    <joint name="transformations/frames/3" type="fixed">
        <origin rpy="-1.570796 0. 0." xyz="0.045 0 0.55"/>
        <parent link="links/upper_arm"/>
        <child link="frames/3"/>
    </joint>

    <joint name="joints/elbow" type="revolute">
        <origin rpy="-1.570796 0 0" xyz="0.045 0 0.55"/>
        <parent link="links/upper_arm"/>
        <child link="links/forearm"/>
        <axis xyz="0 0 1"/>
        <dynamics damping="0.150353" friction="0.854358"/>
        <limit effort="600" lower="-0.9" upper="3.14159" velocity="200"/>
    </joint>

    <joint name="transformations/frames/4" type="fixed">
        <origin rpy="1.570796 0. 0." xyz="-0.045 0 0"/>
        <parent link="links/forearm"/>
        <child link="frames/4"/>
    </joint>

    <joint name="transformations/frames/5" type="fixed">
        <origin rpy="1.570796 0. 0." xyz="-0.045 -0.35 0"/>
        <parent link="links/forearm"/>
        <child link="frames/5"/>
    </joint>

</robot>